<mujoco>
    <!-- <compiler meshdir="resource/meshes" texturedir="resource/materials/textures" /> -->
    <!-- <asset>
      <texture name="test" file="img3.png" type="cube" />
      <material name="test" texture="test" specular="1" shininess="1" />
   </asset> -->
    <visual>
        <global offwidth="1200" offheight="900" />
    </visual>
    <sensor>
        <rangefinder name="rangefider1" site="rangefider1_site" />
        <rangefinder
            name="rangefider2" site="rangefider2_site" />
        <rangefinder name="rangefider3"
            site="rangefider3_site" />
        <rangefinder name="rangefider4" site="rangefider4_site" />
    </sensor>

    <worldbody>
        <light name="uplight" diffuse="1 1 1" pos="0 0 10" dir="0 0 -1" />
        <geom pos="0 0 0" euler="0 0 0" type="plane" size="10 10 0.01" rgba="0.5 0.5 0.5 1" />


        <body pos="2 2 0.25">
            <geom type="box" pos="0.749995669872981 0.4330102018922193 0"
                size="0.49999999999999994 5e-06 0.25" euler="0 0 119.99999999999999" />
            <geom type="box" pos="-0.24999749999999996 0.4330083717652004 0"
                size="0.8660254037844386 5e-06 0.25" euler="0 0 -150.0" />
            <geom type="box" pos="-0.4999964644660942 -0.499996464466094 0"
                size="0.7071067811865476 5e-06 0.25" euler="0 0 -45.000000000000014" />
            <geom type="box" pos="0.49999646446609397 -0.4999964644660941 0"
                size="0.7071067811865476 5e-06 0.25" euler="0 0 44.99999999999999" />
        </body>

        <body pos="-2 -2 0.25">
            <geom type="cylinder" size="1 0.25" />
        </body>

        <body name="robot_0" pos="0 0 0">

            <freejoint name="robot_0"></freejoint>

            <site name="front-flag_0" rgba="0.3 0.3 0.9 1" pos="0 0.17 0.25" type="sphere"
                size="0.03"></site>

            <!-- <body name="balancer_0" pos="0 0 0.05">
                <geom mass="3000" type="sphere" size="0.01"></geom>
            </body> -->

            <body name="front-wheel_0" pos="0 0.14 0.01">
                <joint type="ball" pos="0 0 0"></joint>
                <geom type="sphere" size="0.01"></geom>
            </body>

            <body name="back-wheel_0" pos="0 -0.14 0.01">
                <joint type="ball" pos="0 0 0"></joint>
                <geom type="sphere" size="0.01"></geom>
            </body>

            <body name="left-wheel_0" pos="-0.14 0 0.04" euler="0 90 0">
                <joint damping="0.3" name="left-wheel_0" type="hinge" pos="0 0 0" axis="0 0 -1"></joint>
                <geom rgba="0.1 0.1 0.1 1" type="cylinder" size="0.04 0.005"></geom>
            </body>

            <body name="right-wheel_0" pos="0.14 0 0.04" euler="0 -90 0">
                <joint damping="0.3" name="right-wheel_0" type="hinge" pos="0 0 0" axis="0 0 1"></joint>
                <geom rgba="0.1 0.1 0.1 1" type="cylinder" size="0.04 0.005"></geom>
            </body>
            <body name="shell_0">
                <site type="cylinder" rgba="0.3 0.8 0.3 1" size="0.171 0.101"
                    pos="0 0 0.15"></site>
                <geom type="cylinder" rgba="0.8 0.8 0.8 1" size="0.00889711256 0.10"
                    pos="-0.16105288744000001 5.179855921761719e-17 0.15"></geom>
                <geom type="cylinder" rgba="0.8 0.8 0.8 1" size="0.00889711256 0.10"
                    pos="-0.160170622871362 -0.016834610828921542 0.15"></geom>
                <geom type="cylinder" rgba="0.8 0.8 0.8 1" size="0.00889711256 0.10"
                    pos="-0.15753349544068768 -0.03348477813873268 0.15"></geom>
                <geom type="cylinder" rgba="0.8 0.8 0.8 1" size="0.00889711256 0.10"
                    pos="-0.15317039806796193 -0.04976807921211548 0.15"></geom>
                <geom type="cylinder" rgba="0.8 0.8 0.8 1" size="0.00889711256 0.10"
                    pos="-0.14712913376103712 -0.06550611079501029 0.15"></geom>
                <geom type="cylinder" rgba="0.8 0.8 0.8 1" size="0.00889711256 0.10"
                    pos="-0.13947589187587578 -0.08052644372 0.15"></geom>
                <geom type="cylinder" rgba="0.8 0.8 0.8 1" size="0.00889711256 0.10"
                    pos="-0.13029452293211552 -0.09466451207635171 0.15"></geom>
                <geom type="cylinder" rgba="0.8 0.8 0.8 1" size="0.00889711256 0.10"
                    pos="-0.11968561992922924 -0.10776541622857212 0.15"></geom>
                <geom type="cylinder" rgba="0.8 0.8 0.8 1" size="0.00889711256 0.10"
                    pos="-0.10776541622857215 -0.11968561992922923 0.15"></geom>
                <geom type="cylinder" rgba="0.8 0.8 0.8 1" size="0.00889711256 0.10"
                    pos="-0.09466451207635167 -0.13029452293211555 0.15"></geom>
                <geom type="cylinder" rgba="0.8 0.8 0.8 1" size="0.00889711256 0.10"
                    pos="-0.08052644372000005 -0.13947589187587572 0.15"></geom>
                <geom type="cylinder" rgba="0.8 0.8 0.8 1" size="0.00889711256 0.10"
                    pos="-0.06550611079501033 -0.1471291337610371 0.15"></geom>
                <geom type="cylinder" rgba="0.8 0.8 0.8 1" size="0.00889711256 0.10"
                    pos="-0.04976807921211555 -0.1531703980679619 0.15"></geom>
                <geom type="cylinder" rgba="0.8 0.8 0.8 1" size="0.00889711256 0.10"
                    pos="-0.03348477813873268 -0.15753349544068768 0.15"></geom>
                <geom type="cylinder" rgba="0.8 0.8 0.8 1" size="0.00889711256 0.10"
                    pos="-0.016834610828921584 -0.160170622871362 0.15"></geom>
                <geom type="cylinder" rgba="0.8 0.8 0.8 1" size="0.00889711256 0.10"
                    pos="-2.5899279608808588e-17 -0.16105288744000001 0.15"></geom>
                <geom type="cylinder" rgba="0.8 0.8 0.8 1" size="0.00889711256 0.10"
                    pos="0.016834610828921567 -0.160170622871362 0.15"></geom>
                <geom type="cylinder" rgba="0.8 0.8 0.8 1" size="0.00889711256 0.10"
                    pos="0.033484778138732664 -0.15753349544068768 0.15"></geom>
                <geom type="cylinder" rgba="0.8 0.8 0.8 1" size="0.00889711256 0.10"
                    pos="0.049768079212115526 -0.1531703980679619 0.15"></geom>
                <geom type="cylinder" rgba="0.8 0.8 0.8 1" size="0.00889711256 0.10"
                    pos="0.06550611079501031 -0.1471291337610371 0.15"></geom>
                <geom type="cylinder" rgba="0.8 0.8 0.8 1" size="0.00889711256 0.10"
                    pos="0.08052644372 -0.13947589187587578 0.15"></geom>
                <geom type="cylinder" rgba="0.8 0.8 0.8 1" size="0.00889711256 0.10"
                    pos="0.09466451207635167 -0.13029452293211555 0.15"></geom>
                <geom type="cylinder" rgba="0.8 0.8 0.8 1" size="0.00889711256 0.10"
                    pos="0.10776541622857215 -0.11968561992922923 0.15"></geom>
                <geom type="cylinder" rgba="0.8 0.8 0.8 1" size="0.00889711256 0.10"
                    pos="0.11968561992922923 -0.10776541622857215 0.15"></geom>
                <geom type="cylinder" rgba="0.8 0.8 0.8 1" size="0.00889711256 0.10"
                    pos="0.13029452293211555 -0.09466451207635168 0.15"></geom>
                <geom type="cylinder" rgba="0.8 0.8 0.8 1" size="0.00889711256 0.10"
                    pos="0.13947589187587575 -0.08052644372000001 0.15"></geom>
                <geom type="cylinder" rgba="0.8 0.8 0.8 1" size="0.00889711256 0.10"
                    pos="0.1471291337610371 -0.06550611079501031 0.15"></geom>
                <geom type="cylinder" rgba="0.8 0.8 0.8 1" size="0.00889711256 0.10"
                    pos="0.1531703980679619 -0.04976807921211552 0.15"></geom>
                <geom type="cylinder" rgba="0.8 0.8 0.8 1" size="0.00889711256 0.10"
                    pos="0.15753349544068768 -0.03348477813873268 0.15"></geom>
                <geom type="cylinder" rgba="0.8 0.8 0.8 1" size="0.00889711256 0.10"
                    pos="0.160170622871362 -0.01683461082892157 0.15"></geom>
                <geom type="cylinder" rgba="0.8 0.8 0.8 1" size="0.00889711256 0.10"
                    pos="0.16105288744000001 0.0 0.15"></geom>
                <geom type="cylinder" rgba="0.8 0.8 0.8 1" size="0.00889711256 0.10"
                    pos="0.160170622871362 0.01683461082892157 0.15"></geom>
                <geom type="cylinder" rgba="0.8 0.8 0.8 1" size="0.00889711256 0.10"
                    pos="0.15753349544068768 0.03348477813873268 0.15"></geom>
                <geom type="cylinder" rgba="0.8 0.8 0.8 1" size="0.00889711256 0.10"
                    pos="0.1531703980679619 0.04976807921211552 0.15"></geom>
                <geom type="cylinder" rgba="0.8 0.8 0.8 1" size="0.00889711256 0.10"
                    pos="0.1471291337610371 0.06550611079501031 0.15"></geom>
                <geom type="cylinder" rgba="0.8 0.8 0.8 1" size="0.00889711256 0.10"
                    pos="0.13947589187587575 0.08052644372000001 0.15"></geom>
                <geom type="cylinder" rgba="0.8 0.8 0.8 1" size="0.00889711256 0.10"
                    pos="0.13029452293211555 0.09466451207635168 0.15"></geom>
                <geom type="cylinder" rgba="0.8 0.8 0.8 1" size="0.00889711256 0.10"
                    pos="0.11968561992922923 0.10776541622857215 0.15"></geom>
                <geom type="cylinder" rgba="0.8 0.8 0.8 1" size="0.00889711256 0.10"
                    pos="0.10776541622857215 0.11968561992922923 0.15"></geom>
                <geom type="cylinder" rgba="0.8 0.8 0.8 1" size="0.00889711256 0.10"
                    pos="0.09466451207635167 0.13029452293211555 0.15"></geom>
                <geom type="cylinder" rgba="0.8 0.8 0.8 1" size="0.00889711256 0.10"
                    pos="0.08052644372 0.13947589187587578 0.15"></geom>
                <geom type="cylinder" rgba="0.8 0.8 0.8 1" size="0.00889711256 0.10"
                    pos="0.06550611079501031 0.1471291337610371 0.15"></geom>
                <geom type="cylinder" rgba="0.8 0.8 0.8 1" size="0.00889711256 0.10"
                    pos="0.049768079212115526 0.1531703980679619 0.15"></geom>
                <geom type="cylinder" rgba="0.8 0.8 0.8 1" size="0.00889711256 0.10"
                    pos="0.033484778138732664 0.15753349544068768 0.15"></geom>
                <geom type="cylinder" rgba="0.8 0.8 0.8 1" size="0.00889711256 0.10"
                    pos="0.016834610828921567 0.160170622871362 0.15"></geom>
                <geom type="cylinder" rgba="0.8 0.8 0.8 1" size="0.00889711256 0.10"
                    pos="-2.5899279608808588e-17 0.16105288744000001 0.15"></geom>
                <geom type="cylinder" rgba="0.8 0.8 0.8 1" size="0.00889711256 0.10"
                    pos="-0.016834610828921584 0.160170622871362 0.15"></geom>
                <geom type="cylinder" rgba="0.8 0.8 0.8 1" size="0.00889711256 0.10"
                    pos="-0.03348477813873268 0.15753349544068768 0.15"></geom>
                <geom type="cylinder" rgba="0.8 0.8 0.8 1" size="0.00889711256 0.10"
                    pos="-0.04976807921211555 0.1531703980679619 0.15"></geom>
                <geom type="cylinder" rgba="0.8 0.8 0.8 1" size="0.00889711256 0.10"
                    pos="-0.06550611079501033 0.1471291337610371 0.15"></geom>
                <geom type="cylinder" rgba="0.8 0.8 0.8 1" size="0.00889711256 0.10"
                    pos="-0.08052644372000005 0.13947589187587572 0.15"></geom>
                <geom type="cylinder" rgba="0.8 0.8 0.8 1" size="0.00889711256 0.10"
                    pos="-0.09466451207635167 0.13029452293211555 0.15"></geom>
                <geom type="cylinder" rgba="0.8 0.8 0.8 1" size="0.00889711256 0.10"
                    pos="-0.10776541622857215 0.11968561992922923 0.15"></geom>
                <geom type="cylinder" rgba="0.8 0.8 0.8 1" size="0.00889711256 0.10"
                    pos="-0.11968561992922924 0.10776541622857212 0.15"></geom>
                <geom type="cylinder" rgba="0.8 0.8 0.8 1" size="0.00889711256 0.10"
                    pos="-0.13029452293211552 0.09466451207635171 0.15"></geom>
                <geom type="cylinder" rgba="0.8 0.8 0.8 1" size="0.00889711256 0.10"
                    pos="-0.13947589187587578 0.08052644372 0.15"></geom>
                <geom type="cylinder" rgba="0.8 0.8 0.8 1" size="0.00889711256 0.10"
                    pos="-0.14712913376103712 0.06550611079501029 0.15"></geom>
                <geom type="cylinder" rgba="0.8 0.8 0.8 1" size="0.00889711256 0.10"
                    pos="-0.15317039806796193 0.04976807921211548 0.15"></geom>
                <geom type="cylinder" rgba="0.8 0.8 0.8 1" size="0.00889711256 0.10"
                    pos="-0.15753349544068768 0.03348477813873268 0.15"></geom>
                <geom type="cylinder" rgba="0.8 0.8 0.8 1" size="0.00889711256 0.10"
                    pos="-0.160170622871362 0.016834610828921542 0.15"></geom>
            </body>
        </body>


        <body name="robot_1" pos="0.5 0.5 0">

            <freejoint name="robot_1"></freejoint>

            <site name="front-flag_1" rgba="0.3 0.3 0.9 1" pos="0 0.17 0.25" type="sphere"
                size="0.03"></site>

            <!-- <body name="balancer_1" pos="0 0 0.05">
                <geom mass="3000" type="sphere" size="0.01"></geom>
            </body> -->

            <body name="front-wheel_1" pos="0 0.14 0.01">
                <joint type="ball" pos="0 0 0"></joint>
                <geom type="sphere" size="0.01"></geom>
            </body>

            <body name="back-wheel_1" pos="0 -0.14 0.01">
                <joint type="ball" pos="0 0 0"></joint>
                <geom type="sphere" size="0.01"></geom>
            </body>

            <body name="left-wheel_1" pos="-0.14 0 0.04" euler="0 90 0">
                <joint damping="0.3" name="left-wheel_1" type="hinge" pos="0 0 0" axis="0 0 -1"></joint>
                <geom rgba="0.1 0.1 0.1 1" type="cylinder" size="0.04 0.005"></geom>
            </body>

            <body name="right-wheel_1" pos="0.14 0 0.04" euler="0 -90 0">
                <joint damping="0.3" name="right-wheel_1" type="hinge" pos="0 0 0" axis="0 0 1"></joint>
                <geom rgba="0.1 0.1 0.1 1" type="cylinder" size="0.04 0.005"></geom>
            </body>
            <body name="shell_1">
                <site type="cylinder" rgba="0.3 0.8 0.3 1" size="0.171 0.101"
                    pos="0 0 0.15"></site>
                <geom type="cylinder" rgba="0.8 0.8 0.8 1" size="0.00889711256 0.10"
                    pos="-0.16105288744000001 5.179855921761719e-17 0.15"></geom>
                <geom type="cylinder" rgba="0.8 0.8 0.8 1" size="0.00889711256 0.10"
                    pos="-0.160170622871362 -0.016834610828921542 0.15"></geom>
                <geom type="cylinder" rgba="0.8 0.8 0.8 1" size="0.00889711256 0.10"
                    pos="-0.15753349544068768 -0.03348477813873268 0.15"></geom>
                <geom type="cylinder" rgba="0.8 0.8 0.8 1" size="0.00889711256 0.10"
                    pos="-0.15317039806796193 -0.04976807921211548 0.15"></geom>
                <geom type="cylinder" rgba="0.8 0.8 0.8 1" size="0.00889711256 0.10"
                    pos="-0.14712913376103712 -0.06550611079501029 0.15"></geom>
                <geom type="cylinder" rgba="0.8 0.8 0.8 1" size="0.00889711256 0.10"
                    pos="-0.13947589187587578 -0.08052644372 0.15"></geom>
                <geom type="cylinder" rgba="0.8 0.8 0.8 1" size="0.00889711256 0.10"
                    pos="-0.13029452293211552 -0.09466451207635171 0.15"></geom>
                <geom type="cylinder" rgba="0.8 0.8 0.8 1" size="0.00889711256 0.10"
                    pos="-0.11968561992922924 -0.10776541622857212 0.15"></geom>
                <geom type="cylinder" rgba="0.8 0.8 0.8 1" size="0.00889711256 0.10"
                    pos="-0.10776541622857215 -0.11968561992922923 0.15"></geom>
                <geom type="cylinder" rgba="0.8 0.8 0.8 1" size="0.00889711256 0.10"
                    pos="-0.09466451207635167 -0.13029452293211555 0.15"></geom>
                <geom type="cylinder" rgba="0.8 0.8 0.8 1" size="0.00889711256 0.10"
                    pos="-0.08052644372000005 -0.13947589187587572 0.15"></geom>
                <geom type="cylinder" rgba="0.8 0.8 0.8 1" size="0.00889711256 0.10"
                    pos="-0.06550611079501033 -0.1471291337610371 0.15"></geom>
                <geom type="cylinder" rgba="0.8 0.8 0.8 1" size="0.00889711256 0.10"
                    pos="-0.04976807921211555 -0.1531703980679619 0.15"></geom>
                <geom type="cylinder" rgba="0.8 0.8 0.8 1" size="0.00889711256 0.10"
                    pos="-0.03348477813873268 -0.15753349544068768 0.15"></geom>
                <geom type="cylinder" rgba="0.8 0.8 0.8 1" size="0.00889711256 0.10"
                    pos="-0.016834610828921584 -0.160170622871362 0.15"></geom>
                <geom type="cylinder" rgba="0.8 0.8 0.8 1" size="0.00889711256 0.10"
                    pos="-2.5899279608808588e-17 -0.16105288744000001 0.15"></geom>
                <geom type="cylinder" rgba="0.8 0.8 0.8 1" size="0.00889711256 0.10"
                    pos="0.016834610828921567 -0.160170622871362 0.15"></geom>
                <geom type="cylinder" rgba="0.8 0.8 0.8 1" size="0.00889711256 0.10"
                    pos="0.033484778138732664 -0.15753349544068768 0.15"></geom>
                <geom type="cylinder" rgba="0.8 0.8 0.8 1" size="0.00889711256 0.10"
                    pos="0.049768079212115526 -0.1531703980679619 0.15"></geom>
                <geom type="cylinder" rgba="0.8 0.8 0.8 1" size="0.00889711256 0.10"
                    pos="0.06550611079501031 -0.1471291337610371 0.15"></geom>
                <geom type="cylinder" rgba="0.8 0.8 0.8 1" size="0.00889711256 0.10"
                    pos="0.08052644372 -0.13947589187587578 0.15"></geom>
                <geom type="cylinder" rgba="0.8 0.8 0.8 1" size="0.00889711256 0.10"
                    pos="0.09466451207635167 -0.13029452293211555 0.15"></geom>
                <geom type="cylinder" rgba="0.8 0.8 0.8 1" size="0.00889711256 0.10"
                    pos="0.10776541622857215 -0.11968561992922923 0.15"></geom>
                <geom type="cylinder" rgba="0.8 0.8 0.8 1" size="0.00889711256 0.10"
                    pos="0.11968561992922923 -0.10776541622857215 0.15"></geom>
                <geom type="cylinder" rgba="0.8 0.8 0.8 1" size="0.00889711256 0.10"
                    pos="0.13029452293211555 -0.09466451207635168 0.15"></geom>
                <geom type="cylinder" rgba="0.8 0.8 0.8 1" size="0.00889711256 0.10"
                    pos="0.13947589187587575 -0.08052644372000001 0.15"></geom>
                <geom type="cylinder" rgba="0.8 0.8 0.8 1" size="0.00889711256 0.10"
                    pos="0.1471291337610371 -0.06550611079501031 0.15"></geom>
                <geom type="cylinder" rgba="0.8 0.8 0.8 1" size="0.00889711256 0.10"
                    pos="0.1531703980679619 -0.04976807921211552 0.15"></geom>
                <geom type="cylinder" rgba="0.8 0.8 0.8 1" size="0.00889711256 0.10"
                    pos="0.15753349544068768 -0.03348477813873268 0.15"></geom>
                <geom type="cylinder" rgba="0.8 0.8 0.8 1" size="0.00889711256 0.10"
                    pos="0.160170622871362 -0.01683461082892157 0.15"></geom>
                <geom type="cylinder" rgba="0.8 0.8 0.8 1" size="0.00889711256 0.10"
                    pos="0.16105288744000001 0.0 0.15"></geom>
                <geom type="cylinder" rgba="0.8 0.8 0.8 1" size="0.00889711256 0.10"
                    pos="0.160170622871362 0.01683461082892157 0.15"></geom>
                <geom type="cylinder" rgba="0.8 0.8 0.8 1" size="0.00889711256 0.10"
                    pos="0.15753349544068768 0.03348477813873268 0.15"></geom>
                <geom type="cylinder" rgba="0.8 0.8 0.8 1" size="0.00889711256 0.10"
                    pos="0.1531703980679619 0.04976807921211552 0.15"></geom>
                <geom type="cylinder" rgba="0.8 0.8 0.8 1" size="0.00889711256 0.10"
                    pos="0.1471291337610371 0.06550611079501031 0.15"></geom>
                <geom type="cylinder" rgba="0.8 0.8 0.8 1" size="0.00889711256 0.10"
                    pos="0.13947589187587575 0.08052644372000001 0.15"></geom>
                <geom type="cylinder" rgba="0.8 0.8 0.8 1" size="0.00889711256 0.10"
                    pos="0.13029452293211555 0.09466451207635168 0.15"></geom>
                <geom type="cylinder" rgba="0.8 0.8 0.8 1" size="0.00889711256 0.10"
                    pos="0.11968561992922923 0.10776541622857215 0.15"></geom>
                <geom type="cylinder" rgba="0.8 0.8 0.8 1" size="0.00889711256 0.10"
                    pos="0.10776541622857215 0.11968561992922923 0.15"></geom>
                <geom type="cylinder" rgba="0.8 0.8 0.8 1" size="0.00889711256 0.10"
                    pos="0.09466451207635167 0.13029452293211555 0.15"></geom>
                <geom type="cylinder" rgba="0.8 0.8 0.8 1" size="0.00889711256 0.10"
                    pos="0.08052644372 0.13947589187587578 0.15"></geom>
                <geom type="cylinder" rgba="0.8 0.8 0.8 1" size="0.00889711256 0.10"
                    pos="0.06550611079501031 0.1471291337610371 0.15"></geom>
                <geom type="cylinder" rgba="0.8 0.8 0.8 1" size="0.00889711256 0.10"
                    pos="0.049768079212115526 0.1531703980679619 0.15"></geom>
                <geom type="cylinder" rgba="0.8 0.8 0.8 1" size="0.00889711256 0.10"
                    pos="0.033484778138732664 0.15753349544068768 0.15"></geom>
                <geom type="cylinder" rgba="0.8 0.8 0.8 1" size="0.00889711256 0.10"
                    pos="0.016834610828921567 0.160170622871362 0.15"></geom>
                <geom type="cylinder" rgba="0.8 0.8 0.8 1" size="0.00889711256 0.10"
                    pos="-2.5899279608808588e-17 0.16105288744000001 0.15"></geom>
                <geom type="cylinder" rgba="0.8 0.8 0.8 1" size="0.00889711256 0.10"
                    pos="-0.016834610828921584 0.160170622871362 0.15"></geom>
                <geom type="cylinder" rgba="0.8 0.8 0.8 1" size="0.00889711256 0.10"
                    pos="-0.03348477813873268 0.15753349544068768 0.15"></geom>
                <geom type="cylinder" rgba="0.8 0.8 0.8 1" size="0.00889711256 0.10"
                    pos="-0.04976807921211555 0.1531703980679619 0.15"></geom>
                <geom type="cylinder" rgba="0.8 0.8 0.8 1" size="0.00889711256 0.10"
                    pos="-0.06550611079501033 0.1471291337610371 0.15"></geom>
                <geom type="cylinder" rgba="0.8 0.8 0.8 1" size="0.00889711256 0.10"
                    pos="-0.08052644372000005 0.13947589187587572 0.15"></geom>
                <geom type="cylinder" rgba="0.8 0.8 0.8 1" size="0.00889711256 0.10"
                    pos="-0.09466451207635167 0.13029452293211555 0.15"></geom>
                <geom type="cylinder" rgba="0.8 0.8 0.8 1" size="0.00889711256 0.10"
                    pos="-0.10776541622857215 0.11968561992922923 0.15"></geom>
                <geom type="cylinder" rgba="0.8 0.8 0.8 1" size="0.00889711256 0.10"
                    pos="-0.11968561992922924 0.10776541622857212 0.15"></geom>
                <geom type="cylinder" rgba="0.8 0.8 0.8 1" size="0.00889711256 0.10"
                    pos="-0.13029452293211552 0.09466451207635171 0.15"></geom>
                <geom type="cylinder" rgba="0.8 0.8 0.8 1" size="0.00889711256 0.10"
                    pos="-0.13947589187587578 0.08052644372 0.15"></geom>
                <geom type="cylinder" rgba="0.8 0.8 0.8 1" size="0.00889711256 0.10"
                    pos="-0.14712913376103712 0.06550611079501029 0.15"></geom>
                <geom type="cylinder" rgba="0.8 0.8 0.8 1" size="0.00889711256 0.10"
                    pos="-0.15317039806796193 0.04976807921211548 0.15"></geom>
                <geom type="cylinder" rgba="0.8 0.8 0.8 1" size="0.00889711256 0.10"
                    pos="-0.15753349544068768 0.03348477813873268 0.15"></geom>
                <geom type="cylinder" rgba="0.8 0.8 0.8 1" size="0.00889711256 0.10"
                    pos="-0.160170622871362 0.016834610828921542 0.15"></geom>
            </body>
        </body>


        <body name="robot_2" pos="-0.5 -0.5 0">

            <freejoint name="robot_2"></freejoint>

            <site name="front-flag_2" rgba="0.3 0.3 0.9 1" pos="0 0.17 0.25" type="sphere"
                size="0.03"></site>

            <!-- <body name="balancer_2" pos="0 0 0.05">
                <geom mass="3000" type="sphere" size="0.01"></geom>
            </body> -->

            <body name="front-wheel_2" pos="0 0.14 0.01">
                <joint type="ball" pos="0 0 0"></joint>
                <geom type="sphere" size="0.01"></geom>
            </body>

            <body name="back-wheel_2" pos="0 -0.14 0.01">
                <joint type="ball" pos="0 0 0"></joint>
                <geom type="sphere" size="0.01"></geom>
            </body>

            <body name="left-wheel_2" pos="-0.14 0 0.04" euler="0 90 0">
                <joint damping="0.3" name="left-wheel_2" type="hinge" pos="0 0 0" axis="0 0 -1"></joint>
                <geom rgba="0.1 0.1 0.1 1" type="cylinder" size="0.04 0.005"></geom>
            </body>

            <body name="right-wheel_2" pos="0.14 0 0.04" euler="0 -90 0">
                <joint damping="0.3" name="right-wheel_2" type="hinge" pos="0 0 0" axis="0 0 1"></joint>
                <geom rgba="0.1 0.1 0.1 1" type="cylinder" size="0.04 0.005"></geom>
            </body>
            <body name="shell_2">
                <site type="cylinder" rgba="0.3 0.8 0.3 1" size="0.171 0.101"
                    pos="0 0 0.15"></site>
                <geom type="cylinder" rgba="0.8 0.8 0.8 1" size="0.00889711256 0.10"
                    pos="-0.16105288744000001 5.179855921761719e-17 0.15"></geom>
                <geom type="cylinder" rgba="0.8 0.8 0.8 1" size="0.00889711256 0.10"
                    pos="-0.160170622871362 -0.016834610828921542 0.15"></geom>
                <geom type="cylinder" rgba="0.8 0.8 0.8 1" size="0.00889711256 0.10"
                    pos="-0.15753349544068768 -0.03348477813873268 0.15"></geom>
                <geom type="cylinder" rgba="0.8 0.8 0.8 1" size="0.00889711256 0.10"
                    pos="-0.15317039806796193 -0.04976807921211548 0.15"></geom>
                <geom type="cylinder" rgba="0.8 0.8 0.8 1" size="0.00889711256 0.10"
                    pos="-0.14712913376103712 -0.06550611079501029 0.15"></geom>
                <geom type="cylinder" rgba="0.8 0.8 0.8 1" size="0.00889711256 0.10"
                    pos="-0.13947589187587578 -0.08052644372 0.15"></geom>
                <geom type="cylinder" rgba="0.8 0.8 0.8 1" size="0.00889711256 0.10"
                    pos="-0.13029452293211552 -0.09466451207635171 0.15"></geom>
                <geom type="cylinder" rgba="0.8 0.8 0.8 1" size="0.00889711256 0.10"
                    pos="-0.11968561992922924 -0.10776541622857212 0.15"></geom>
                <geom type="cylinder" rgba="0.8 0.8 0.8 1" size="0.00889711256 0.10"
                    pos="-0.10776541622857215 -0.11968561992922923 0.15"></geom>
                <geom type="cylinder" rgba="0.8 0.8 0.8 1" size="0.00889711256 0.10"
                    pos="-0.09466451207635167 -0.13029452293211555 0.15"></geom>
                <geom type="cylinder" rgba="0.8 0.8 0.8 1" size="0.00889711256 0.10"
                    pos="-0.08052644372000005 -0.13947589187587572 0.15"></geom>
                <geom type="cylinder" rgba="0.8 0.8 0.8 1" size="0.00889711256 0.10"
                    pos="-0.06550611079501033 -0.1471291337610371 0.15"></geom>
                <geom type="cylinder" rgba="0.8 0.8 0.8 1" size="0.00889711256 0.10"
                    pos="-0.04976807921211555 -0.1531703980679619 0.15"></geom>
                <geom type="cylinder" rgba="0.8 0.8 0.8 1" size="0.00889711256 0.10"
                    pos="-0.03348477813873268 -0.15753349544068768 0.15"></geom>
                <geom type="cylinder" rgba="0.8 0.8 0.8 1" size="0.00889711256 0.10"
                    pos="-0.016834610828921584 -0.160170622871362 0.15"></geom>
                <geom type="cylinder" rgba="0.8 0.8 0.8 1" size="0.00889711256 0.10"
                    pos="-2.5899279608808588e-17 -0.16105288744000001 0.15"></geom>
                <geom type="cylinder" rgba="0.8 0.8 0.8 1" size="0.00889711256 0.10"
                    pos="0.016834610828921567 -0.160170622871362 0.15"></geom>
                <geom type="cylinder" rgba="0.8 0.8 0.8 1" size="0.00889711256 0.10"
                    pos="0.033484778138732664 -0.15753349544068768 0.15"></geom>
                <geom type="cylinder" rgba="0.8 0.8 0.8 1" size="0.00889711256 0.10"
                    pos="0.049768079212115526 -0.1531703980679619 0.15"></geom>
                <geom type="cylinder" rgba="0.8 0.8 0.8 1" size="0.00889711256 0.10"
                    pos="0.06550611079501031 -0.1471291337610371 0.15"></geom>
                <geom type="cylinder" rgba="0.8 0.8 0.8 1" size="0.00889711256 0.10"
                    pos="0.08052644372 -0.13947589187587578 0.15"></geom>
                <geom type="cylinder" rgba="0.8 0.8 0.8 1" size="0.00889711256 0.10"
                    pos="0.09466451207635167 -0.13029452293211555 0.15"></geom>
                <geom type="cylinder" rgba="0.8 0.8 0.8 1" size="0.00889711256 0.10"
                    pos="0.10776541622857215 -0.11968561992922923 0.15"></geom>
                <geom type="cylinder" rgba="0.8 0.8 0.8 1" size="0.00889711256 0.10"
                    pos="0.11968561992922923 -0.10776541622857215 0.15"></geom>
                <geom type="cylinder" rgba="0.8 0.8 0.8 1" size="0.00889711256 0.10"
                    pos="0.13029452293211555 -0.09466451207635168 0.15"></geom>
                <geom type="cylinder" rgba="0.8 0.8 0.8 1" size="0.00889711256 0.10"
                    pos="0.13947589187587575 -0.08052644372000001 0.15"></geom>
                <geom type="cylinder" rgba="0.8 0.8 0.8 1" size="0.00889711256 0.10"
                    pos="0.1471291337610371 -0.06550611079501031 0.15"></geom>
                <geom type="cylinder" rgba="0.8 0.8 0.8 1" size="0.00889711256 0.10"
                    pos="0.1531703980679619 -0.04976807921211552 0.15"></geom>
                <geom type="cylinder" rgba="0.8 0.8 0.8 1" size="0.00889711256 0.10"
                    pos="0.15753349544068768 -0.03348477813873268 0.15"></geom>
                <geom type="cylinder" rgba="0.8 0.8 0.8 1" size="0.00889711256 0.10"
                    pos="0.160170622871362 -0.01683461082892157 0.15"></geom>
                <geom type="cylinder" rgba="0.8 0.8 0.8 1" size="0.00889711256 0.10"
                    pos="0.16105288744000001 0.0 0.15"></geom>
                <geom type="cylinder" rgba="0.8 0.8 0.8 1" size="0.00889711256 0.10"
                    pos="0.160170622871362 0.01683461082892157 0.15"></geom>
                <geom type="cylinder" rgba="0.8 0.8 0.8 1" size="0.00889711256 0.10"
                    pos="0.15753349544068768 0.03348477813873268 0.15"></geom>
                <geom type="cylinder" rgba="0.8 0.8 0.8 1" size="0.00889711256 0.10"
                    pos="0.1531703980679619 0.04976807921211552 0.15"></geom>
                <geom type="cylinder" rgba="0.8 0.8 0.8 1" size="0.00889711256 0.10"
                    pos="0.1471291337610371 0.06550611079501031 0.15"></geom>
                <geom type="cylinder" rgba="0.8 0.8 0.8 1" size="0.00889711256 0.10"
                    pos="0.13947589187587575 0.08052644372000001 0.15"></geom>
                <geom type="cylinder" rgba="0.8 0.8 0.8 1" size="0.00889711256 0.10"
                    pos="0.13029452293211555 0.09466451207635168 0.15"></geom>
                <geom type="cylinder" rgba="0.8 0.8 0.8 1" size="0.00889711256 0.10"
                    pos="0.11968561992922923 0.10776541622857215 0.15"></geom>
                <geom type="cylinder" rgba="0.8 0.8 0.8 1" size="0.00889711256 0.10"
                    pos="0.10776541622857215 0.11968561992922923 0.15"></geom>
                <geom type="cylinder" rgba="0.8 0.8 0.8 1" size="0.00889711256 0.10"
                    pos="0.09466451207635167 0.13029452293211555 0.15"></geom>
                <geom type="cylinder" rgba="0.8 0.8 0.8 1" size="0.00889711256 0.10"
                    pos="0.08052644372 0.13947589187587578 0.15"></geom>
                <geom type="cylinder" rgba="0.8 0.8 0.8 1" size="0.00889711256 0.10"
                    pos="0.06550611079501031 0.1471291337610371 0.15"></geom>
                <geom type="cylinder" rgba="0.8 0.8 0.8 1" size="0.00889711256 0.10"
                    pos="0.049768079212115526 0.1531703980679619 0.15"></geom>
                <geom type="cylinder" rgba="0.8 0.8 0.8 1" size="0.00889711256 0.10"
                    pos="0.033484778138732664 0.15753349544068768 0.15"></geom>
                <geom type="cylinder" rgba="0.8 0.8 0.8 1" size="0.00889711256 0.10"
                    pos="0.016834610828921567 0.160170622871362 0.15"></geom>
                <geom type="cylinder" rgba="0.8 0.8 0.8 1" size="0.00889711256 0.10"
                    pos="-2.5899279608808588e-17 0.16105288744000001 0.15"></geom>
                <geom type="cylinder" rgba="0.8 0.8 0.8 1" size="0.00889711256 0.10"
                    pos="-0.016834610828921584 0.160170622871362 0.15"></geom>
                <geom type="cylinder" rgba="0.8 0.8 0.8 1" size="0.00889711256 0.10"
                    pos="-0.03348477813873268 0.15753349544068768 0.15"></geom>
                <geom type="cylinder" rgba="0.8 0.8 0.8 1" size="0.00889711256 0.10"
                    pos="-0.04976807921211555 0.1531703980679619 0.15"></geom>
                <geom type="cylinder" rgba="0.8 0.8 0.8 1" size="0.00889711256 0.10"
                    pos="-0.06550611079501033 0.1471291337610371 0.15"></geom>
                <geom type="cylinder" rgba="0.8 0.8 0.8 1" size="0.00889711256 0.10"
                    pos="-0.08052644372000005 0.13947589187587572 0.15"></geom>
                <geom type="cylinder" rgba="0.8 0.8 0.8 1" size="0.00889711256 0.10"
                    pos="-0.09466451207635167 0.13029452293211555 0.15"></geom>
                <geom type="cylinder" rgba="0.8 0.8 0.8 1" size="0.00889711256 0.10"
                    pos="-0.10776541622857215 0.11968561992922923 0.15"></geom>
                <geom type="cylinder" rgba="0.8 0.8 0.8 1" size="0.00889711256 0.10"
                    pos="-0.11968561992922924 0.10776541622857212 0.15"></geom>
                <geom type="cylinder" rgba="0.8 0.8 0.8 1" size="0.00889711256 0.10"
                    pos="-0.13029452293211552 0.09466451207635171 0.15"></geom>
                <geom type="cylinder" rgba="0.8 0.8 0.8 1" size="0.00889711256 0.10"
                    pos="-0.13947589187587578 0.08052644372 0.15"></geom>
                <geom type="cylinder" rgba="0.8 0.8 0.8 1" size="0.00889711256 0.10"
                    pos="-0.14712913376103712 0.06550611079501029 0.15"></geom>
                <geom type="cylinder" rgba="0.8 0.8 0.8 1" size="0.00889711256 0.10"
                    pos="-0.15317039806796193 0.04976807921211548 0.15"></geom>
                <geom type="cylinder" rgba="0.8 0.8 0.8 1" size="0.00889711256 0.10"
                    pos="-0.15753349544068768 0.03348477813873268 0.15"></geom>
                <geom type="cylinder" rgba="0.8 0.8 0.8 1" size="0.00889711256 0.10"
                    pos="-0.160170622871362 0.016834610828921542 0.15"></geom>
            </body>
        </body>

        <body pos="-1 0 0.1">
            <geom type="box" size="0.3 0.2 0.1" rgba="0 0 1 1"
                euler="0 0 0"></geom>
            <site rgba="1 0 0 1" pos="0 0 0.1" euler="-90 0 0"
                name="rangefider1_site" />
            <site rgba="1 0 0 1" pos="0 0 0.1" euler="-90 90 0"
                name="rangefider2_site" />
            <site rgba="1 0 0 1" pos="0 0 0.1" euler="-90 180 0"
                name="rangefider3_site" />
            <site rgba="1 0 0 1" pos="0 0 0.1" euler="-90 270 0"
                name="rangefider4_site" />
        </body>
    </worldbody>

    <actuator>
        <velocity name="left-velocity-servo_0" joint="left-wheel_0" kv="0.05" />
        <velocity name="right-velocity-servo_0" joint="right-wheel_0" kv="0.05" />
    </actuator>


    <actuator>
        <velocity name="left-velocity-servo_1" joint="left-wheel_1" kv="0.05" />
        <velocity name="right-velocity-servo_1" joint="right-wheel_1" kv="0.05" />
    </actuator>


    <actuator>
        <velocity name="left-velocity-servo_2" joint="left-wheel_2" kv="0.05" />
        <velocity name="right-velocity-servo_2" joint="right-wheel_2" kv="0.05" />
    </actuator>



</mujoco>
